<?xml version="1.0" ?>
<!-- =================================================================================== -->
<!-- |    This document was autogenerated by xacro from rescue_robot.xacro             | -->
<!-- |    EDITING THIS FILE BY HAND IS NOT RECOMMENDED                                 | -->
<!-- =================================================================================== -->
<robot name="rescue_bot">
  <!-- base -->
  <link name="base_link">
    <visual>
      <geometry>
        <mesh filename="/home/kfcnef/AESIR/simulation_rescue_major/src/install/robot_description/share/robot_description/meshes/base.stl" scale="0.001 0.001 0.001"/>
      </geometry>
    </visual>
    <collision>
      <geometry>
        <mesh filename="/home/kfcnef/AESIR/simulation_rescue_major/src/install/robot_description/share/robot_description/meshes/base.stl" scale="0.001 0.001 0.001"/>
      </geometry>
    </collision>
    <!-- crude inertial placeholder: update with real values -->
    <inertial>
      <origin rpy="0 0 0" xyz="0 0 0"/>
      <mass value="5.0"/>
      <inertia ixx="0.2" ixy="0" ixz="0" iyy="0.2" iyz="0" izz="0.2"/>
    </inertial>
  </link>
  <!-- flipper 1 -->
  <link name="flipper_1_link">
    <visual>
      <geometry>
        <mesh filename="/home/kfcnef/AESIR/simulation_rescue_major/src/install/robot_description/share/robot_description/meshes/flipper_1.stl" scale="0.001 0.001 0.001"/>
      </geometry>
    </visual>
    <collision>
      <geometry>
        <mesh filename="/home/kfcnef/AESIR/simulation_rescue_major/src/install/robot_description/share/robot_description/meshes/flipper_1.stl" scale="0.001 0.001 0.001"/>
      </geometry>
    </collision>
    <inertial>
      <origin rpy="0 0 0" xyz="0 0 0"/>
      <mass value="0.8"/>
      <inertia ixx="0.01" ixy="0" ixz="0" iyy="0.02" iyz="0" izz="0.02"/>
    </inertial>
  </link>
  <!-- joint flipper 1 (adjust origin/axis to your model!) -->
  <joint name="flipper_1_joint" type="revolute">
    <parent link="base_link"/>
    <child link="flipper_1_link"/>
    <!-- joint frame at the hinge center in base_link coordinates -->
    <origin rpy="0 0 0" xyz="0 0 0"/>
    <!-- rotation axis (example: Y axis) -->
    <axis xyz="0 1 0"/>
    <limit effort="10" lower="0" upper="1.57" velocity="1.0"/>
    <!-- optional damping/friction -->
    <!-- <dynamics damping="0.1" friction="0.0"/> -->
  </joint>
  <!-- flipper 2 -->
  <link name="flipper_2_link">
    <visual>
      <geometry>
        <mesh filename="/home/kfcnef/AESIR/simulation_rescue_major/src/install/robot_description/share/robot_description/meshes/flipper_2.stl" scale="0.001 0.001 0.001"/>
      </geometry>
    </visual>
    <collision>
      <geometry>
        <mesh filename="/home/kfcnef/AESIR/simulation_rescue_major/src/install/robot_description/share/robot_description/meshes/flipper_2.stl" scale="0.001 0.001 0.001"/>
      </geometry>
    </collision>
    <inertial>
      <origin rpy="0 0 0" xyz="0 0 0"/>
      <mass value="0.8"/>
      <inertia ixx="0.01" ixy="0" ixz="0" iyy="0.02" iyz="0" izz="0.02"/>
    </inertial>
  </link>
  <!-- joint flipper 2 (adjust origin/axis to your model!) -->
  <joint name="flipper_2_joint" type="revolute">
    <parent link="base_link"/>
    <child link="flipper_2_link"/>
    <!-- joint frame at the hinge center in base_link coordinates -->
    <origin rpy="0 0 0" xyz="0 0 0"/>
    <!-- rotation axis (example: Y axis) -->
    <axis xyz="0 1 0"/>
    <limit effort="10" lower="0" upper="1.57" velocity="1.0"/>
    <!-- optional damping/friction -->
    <!-- <dynamics damping="0.1" friction="0.0"/> -->
  </joint>
  <!-- flipper 3 -->
  <link name="flipper_3_link">
    <visual>
      <geometry>
        <mesh filename="/home/kfcnef/AESIR/simulation_rescue_major/src/install/robot_description/share/robot_description/meshes/flipper_3.stl" scale="0.001 0.001 0.001"/>
      </geometry>
    </visual>
    <collision>
      <geometry>
        <mesh filename="/home/kfcnef/AESIR/simulation_rescue_major/src/install/robot_description/share/robot_description/meshes/flipper_3.stl" scale="0.001 0.001 0.001"/>
      </geometry>
    </collision>
    <inertial>
      <origin rpy="0 0 0" xyz="0 0 0"/>
      <mass value="0.8"/>
      <inertia ixx="0.01" ixy="0" ixz="0" iyy="0.02" iyz="0" izz="0.02"/>
    </inertial>
  </link>
  <!-- joint flipper 3 (adjust origin/axis to your model!) -->
  <joint name="flipper_3_joint" type="revolute">
    <parent link="base_link"/>
    <child link="flipper_3_link"/>
    <!-- joint frame at the hinge center in base_link coordinates -->
    <origin rpy="0 0 0" xyz="0 0 0"/>
    <!-- rotation axis (example: Y axis) -->
    <axis xyz="0 1 0"/>
    <limit effort="10" lower="0" upper="1.57" velocity="1.0"/>
    <!-- optional damping/friction -->
    <!-- <dynamics damping="0.1" friction="0.0"/> -->
  </joint>
  <!-- flipper 4 -->
  <link name="flipper_4_link">
    <visual>
      <geometry>
        <mesh filename="/home/kfcnef/AESIR/simulation_rescue_major/src/install/robot_description/share/robot_description/meshes/flipper_4.stl" scale="0.001 0.001 0.001"/>
      </geometry>
    </visual>
    <collision>
      <geometry>
        <mesh filename="/home/kfcnef/AESIR/simulation_rescue_major/src/install/robot_description/share/robot_description/meshes/flipper_4.stl" scale="0.001 0.001 0.001"/>
      </geometry>
    </collision>
    <inertial>
      <origin rpy="0 0 0" xyz="0 0 0"/>
      <mass value="0.8"/>
      <inertia ixx="0.01" ixy="0" ixz="0" iyy="0.02" iyz="0" izz="0.02"/>
    </inertial>
  </link>
  <!-- joint flipper 4 (adjust origin/axis to your model!) -->
  <joint name="flipper_4_joint" type="revolute">
    <parent link="base_link"/>
    <child link="flipper_4_link"/>
    <!-- joint frame at the hinge center in base_link coordinates -->
    <origin rpy="0 0 0" xyz="0 0 0"/>
    <!-- rotation axis (example: Y axis) -->
    <axis xyz="0 1 0"/>
    <limit effort="10" lower="0" upper="1.57" velocity="1.0"/>
    <!-- optional damping/friction -->
    <!-- <dynamics damping="0.1" friction="0.0"/> -->
  </joint>
</robot>
