<?xml version="1.0"?>
<sdf version="1.8">
  <model name="rescue_bot">
    <pose>0 0 0 0 0 0</pose>

    <!-- base -->
    <link name="base_link">
      <inertial><mass>10</mass>
        <inertia><ixx>0.1</ixx><iyy>0.1</iyy><izz>0.1</izz></inertia>
      </inertial>
      <collision name="base_col"><geometry><box><size>0.5 0.3 0.1</size></box></geometry></collision>
      <visual   name="base_vis"><geometry><box><size>0.5 0.3 0.1</size></box></geometry></visual>
    </link>

    <!-- ruedas -->
    <link name="left_wheel">
      <inertial><mass>0.5</mass><inertia><ixx>0.001</ixx><iyy>0.001</iyy><izz>0.001</izz></inertia></inertial>
      <collision name="c"><geometry><cylinder><radius>0.08</radius><length>0.04</length></cylinder></geometry></collision>
      <visual   name="v"><geometry><cylinder><radius>0.08</radius><length>0.04</length></cylinder></geometry></visual>
    </link>
    <joint name="left_wheel_joint" type="revolute">
      <parent>base_link</parent><child>left_wheel</child>
      <pose>0 0 0 0 0 0</pose>
      <axis><xyz>0 1 0</xyz><limit><lower>-1e16</lower><upper>1e16</upper></limit></axis>
    </joint>

    <link name="right_wheel">
      <inertial>
        <mass>0.5</mass>
        <inertia>
          <ixx>0.001</ixx><iyy>0.001</iyy><izz>0.001</izz>
        </inertia>
      </inertial>
      <collision name="c">
        <geometry>
          <cylinder><radius>0.08</radius><length>0.04</length></cylinder>
        </geometry>
      </collision>
      <visual name="v">
        <geometry>
          <cylinder><radius>0.08</radius><length>0.04</length></cylinder>
        </geometry>
      </visual>
    </link>

    <joint name="right_wheel_joint" type="revolute">
      <parent>base_link</parent>
      <child>right_wheel</child>
      <pose>0 0 0 0 0 0</pose>
      <axis>
        <xyz>0 1 0</xyz>
        <limit><lower>-1e16</lower><upper>1e16</upper></limit>
      </axis>
    </joint>

    <!-- LIDAR sim (ray) opcional -->
    <link name="lidar_link">
      <sensor name="lidar" type="gpu_lidar">
        <update_rate>15</update_rate>
        <ray>
          <scan><horizontal><samples>720</samples><resolution>1</resolution><min_angle>-3.14</min_angle><max_angle>3.14</max_angle></horizontal></scan>
          <range><min>0.12</min><max>12.0</max></range>
        </ray>
        <topic>/lidar</topic>
      </sensor>
    </link>
    <joint name="lidar_joint" type="fixed"><parent>base_link</parent><child>lidar_link</child></joint>

    <!-- Dif. drive -->
    <plugin name="gz::sim::systems::DiffDrive" filename="libgz-sim-diff-drive-system.so">
      <left_joint>left_wheel_joint</left_joint>
      <right_joint>right_wheel_joint</right_joint>
      <wheel_separation>0.28</wheel_separation>
      <wheel_radius>0.08</wheel_radius>
      <topic>/cmd_vel</topic>
      <odom_topic>/odom</odom_topic>
      <odom_frame>odom</odom_frame>
      <robot_base_frame>base_link</robot_base_frame>
      <publish_odom>true</publish_odom>
      <publish_tf>false</publish_tf> <!-- TF lo da robot_state_publisher -->
    </plugin>
  </model>
</sdf>
